tests/complex_36.in
40
o
28 S 101 ATAQ 499 370
15 C 100
4 S 103 AVAL 1641 487
29 C 101
2 C 101
19 S 106 BIO/B 577 422
7 B 107 ARI 1942 761
39 B 108 AEM 1893 913
29 S 109 BC 1663 573
32 S 110 BBWI 357 790
36 C 102
8 C 109
31 C 107
28 S 114 ACM 469 519
32 C 110
39 B 116 AME 1001 577
22 B 117 ATH^B 363 953
19 S 118 AXR 519 112
21 S 119 ABR 1683 582
26 B 120 AIC 1922 389
23 S 121 BAC^S 251 120
0 C 115
33 C 104
19 B 124 AM 723 412
31 S 125 BIPC 1984 893
16 S 126 ALE 696 512
36 B 127 AFB 1993 321
26 B 128 BALL 1317 17
24 C 123
31 S 130 BBN 1017 645
0 S 131 AFG 758 204
35 B 132 BKU 337 947
6 B 133 ADCT 1982 216
31 C 132
28 S 135 ALL 876 350
5 S 136 BBLN 970 453
9 C 135
3 B 138 AGL 1739 913
22 S 139 AGM^D 1992 371
38 B 140 ARGD 1963 599
34 S 141 ACHR 1342 698
5 S 142 BKU 1950 845
17 B 143 ARI 1181 761
15 C 136
10 S 145 ALLE 1289 806
7 C 110
3 C 127
22 C 147
24 C 101
32 B 150 BBAR 1258 706
4 C 121
3 S 152 BGY 1708 786
10 B 153 BGY 1002 763
28 C 121
36 C 129
3 C 143
20 C 156
31 S 158 BFK 1138 293
23 C 148
32 S 160 AMWL 1125 365
11 B 161 AMWL 1605 525
0 S 162 APLE 1689 480
37 S 163 ARC 494 34
36 C 129
34 C 121
5 C 156
34 S 167 AXTA 933 801
19 S 168 AYI 907 536
12 S 169 ATCO^I 887 259
21 C 129
24 B 171 BFS^E 1511 902
31 S 172 AIO 1097 305
32 S 173 AEVA 309 910
18 S 174 ACR 1202 341
13 S 175 BIP 1968 711
15 S 176 BILL 1148 491
10 C 107
35 C 154
38 B 179 BCS 1008 797
6 B 180 AMRX 1591 58
17 S 181 ATEN 538 575
32 C 107
12 S 183 AUY 212 581
35 S 184 AQUA 1981 385
20 B 185 ALTG^A 612 112
37 C 147
2 C 127
4 C 177
8 B 189 AVK 547 958
27 C 143
20 C 166
22 S 192 BIPC 1085 919
14 B 193 BDX 1336 76
19 S 194 AVTR 1845 292
36 S 195 ACA 253 492
24 C 137
30 S 197 AIO 1631 206
27 S 198 AMT 488 774
18 B 199 AHL^C 1252 690
35 B 200 ALL^H 868 753
10 C 164
20 S 202 AHT 1296 272
8 S 203 ARL 1532 732
28 B 204 AGM 1511 173
28 C 121
5 B 206 AIZN 1030 437
10 B 207 ARIS 179 442
14 C 207
26 S 209 BFH 1548 860
35 B 210 BIP 1807 94
9 S 211 BCX 1050 690
15 S 212 BBD 804 43
34 C 129
37 S 214 AAIC^C 527 713
11 B 215 ATKR 1756 617
37 S 216 AQN 737 446
8 B 217 ARL 1696 574
27 S 218 ATO 1919 559
27 C 177
22 S 220 AWP 1011 947
0 S 221 BLK 1603 292
21 B 222 ATIP 1356 862
5 S 223 AKR 1966 656
3 B 224 AME 253 95
37 C 161
27 S 226 BAM 279 120
14 S 227 AOS 973 633
24 C 167
20 C 216
3 S 230 APCA 873 259
23 S 231 AQNA 977 327
38 B 232 AIG^A 742 987
5 B 233 APAM 591 161
32 C 145
10 C 192
35 C 235
34 S 237 ALL^I 639 28
13 C 200
8 S 239 BGB 1748 70
21 B 240 BCSF 1137 854
39 S 241 BMA 281 437
36 S 242 AQNU 942 459
24 C 177
27 B 244 AJG 1190 363
4 C 106
19 B 246 BBY 1729 866
16 C 128
22 S 248 B 1284 379
16 B 249 AYI 1346 912
3 B 250 AZO 649 294
30 C 202
4 C 198
12 C 139
6 C 208
8 B 255 BDN 648 100
39 C 211
11 C 190
28 C 238
27 C 173
26 S 260 AAIC 181 108
29 S 261 AMG 1083 973
7 B 262 ALL 815 70
7 S 263 BBLN 1585 273
38 C 131
26 B 265 BFS^D 1410 415
9 C 219
4 S 267 BKDT 759 16
29 C 171
39 C 181
26 C 181
28 B 271 AKR 1147 295
23 C 234
10 B 273 BBU 153 984
25 S 274 AVA 911 591
18 C 143
21 B 276 ABBV 1088 824
39 S 277 AMC 1536 855
1 C 133
13 S 279 APGB 121 933
1 S 280 AMX 1928 849
7 S 281 ATR 1302 72
14 B 282 BHV 412 681
25 S 283 BAP 203 162
24 C 194
28 C 130
26 B 286 AJG 214 420
11 C 164
28 S 288 BIPC 1566 381
10 S 289 AZRE 1489 531
30 C 235
35 B 291 AHT^H 751 859
24 S 292 AGCO 813 955
22 B 293 BKU 1999 214
13 C 140
11 C 175
7 S 296 BHVN 1360 958
6 C 205
15 S 298 ATHM 250 78
8 S 299 BEDU 782 113
0 C 197
20 B 301 AROC 1464 112
10 C 207
13 S 303 AR 277 187
30 S 304 AGX 874 76
37 S 305 AQUA 1033 411
6 C 275
26 C 211
17 S 308 BFAC 1736 111
12 B 309 BALL 1196 322
5 B 310 BIGZ 1880 348
6 B 311 ARE 220 343
26 B 312 AVAL 367 771
8 B 313 AA 253 917
9 S 314 BHR^D 1471 129
2 C 210
12 B 316 BML^J 834 779
14 B 317 ADT 310 575
31 S 318 BHVN 133 859
19 C 186
33 B 320 ALK 490 498
19 S 321 BMA 103 801
4 B 322 ALEX 115 592
20 B 323 ARGD 1313 95
22 S 324 AOMR 1388 513
33 B 325 BAC^Q 563 768
7 C 172
3 B 327 BEN 545 843
17 C 112
26 B 329 ADX 591 817
12 C 180
37 S 331 BKKT 1203 487
20 B 332 ALL^H 944 400
17 B 333 ALLG 935 650
19 B 334 BCAT 1955 882
6 S 335 BHR 465 60
29 S 336 ADT 1881 634
28 S 337 AOMR 1307 842
18 S 338 AIU 1419 384
27 C 247
36 C 294
8 S 341 AHT^H 1832 249
36 C 150
25 B 343 AESC 533 908
25 B 344 AMG 817 634
11 B 345 BIPH 1151 631
34 C 159
32 C 304
22 B 348 BEKE 1593 21
38 C 246
36 B 350 BKH 925 18
16 B 351 AZO 237 541
30 S 352 AXS^E 273 657
18 S 353 ARW 626 875
36 C 230
16 B 355 BABA 1535 485
13 B 356 BGR 1740 734
36 C 150
16 S 358 ARI 881 974
6 S 359 BAC^Q 355 684
25 B 360 ACP 1125 614
12 B 361 ABR^D 104 210
13 B 362 BFAM 438 211
27 S 363 AL^A 1063 672
10 B 364 AMT 1429 290
37 S 365 ATGE 1422 89
13 B 366 AMC 668 148
19 S 367 AQNA 1616 723
9 C 332
23 S 369 ACP^A 1182 38
1 C 333
3 S 371 BAX 349 469
14 B 372 BEPC 1112 793
28 C 355
28 B 374 BFH 1104 327
26 S 375 BAC^S 570 975
27 C 293
22 C 215
18 C 205
2 C 234
5 C 362
18 S 381 ACEL 949 574
33 S 382 AVB 847 327
0 B 383 ATGE 339 352
22 B 384 AAIC 1828 489
23 C 270
21 B 386 BBAI 1927 582
10 S 387 AMT 1322 338
34 B 388 BME 1332 368
21 C 294
13 C 225
22 B 391 BDC 1172 317
24 S 392 ALC 1504 508
10 C 288
38 B 394 BCE 320 193
29 S 395 BML^G 663 44
31 C 264
23 C 331
17 B 398 AI 1239 914
5 S 399 APG 1030 928
22 C 128
5 B 401 BFAM 1888 673
23 S 402 BFH 208 444
29 S 403 ABEV 182 46
5 S 404 BHR^B 1485 876
29 S 405 AIF 1086 876
25 C 146
11 C 353
11 S 408 BGR 937 185
37 C 322
7 B 410 AROC 1672 600
26 C 179
22 S 412 AMN 1282 410
24 C 337
32 B 414 APLE 1725 557
9 C 147
25 C 164
37 B 417 ANET 185 691
32 S 418 BHV 614 70
13 B 419 AIF 466 194
29 S 420 AGO 1844 403
8 C 159
31 C 323
32 B 423 AIZN 290 612
27 B 424 ALLE 1430 631
18 S 425 BBAI 970 189
32 B 426 BML^J 984 458
17 B 427 AJX 194 507
32 S 428 AKO/A 585 705
20 S 429 AVK 1857 596
35 S 430 AGM^D 1147 206
21 S 431 AES 1961 853
6 C 305
29 S 433 BLK 1337 41
27 S 434 BEPC 399 369
22 S 435 AL^A 1128 762
32 S 436 ACCO 1154 536
21 S 437 AFGD 1641 855
6 S 438 AIZ 993 843
33 C 133
36 B 440 ATEK 719 224
9 S 441 BDX 870 320
11 S 442 ABBV 650 191
23 B 443 AAIC 1894 538
0 B 444 AVY 1704 375
38 B 445 BA 455 721
34 C 206
15 B 447 BBDO 416 677
36 C 272
4 S 449 AEL 399 173
38 C 266
22 C 337
39 B 452 ABR^D 449 901
33 B 453 ALX 746 276
10 C 191
6 C 245
10 S 456 BKI 967 155
1 S 457 ALSN 1882 377
29 C 314
28 C 352
4 B 460 AIN 153 994
23 C 179
23 C 193
1 S 463 BF/A 699 271
4 C 201
4 C 396
8 S 466 AROC 268 342
17 C 184
39 S 468 ABR^F 952 246
9 C 151
7 S 470 BMAC 1802 961
10 B 471 ABR^D 1341 374
7 S 472 ARR 991 23
28 C 258
25 S 474 AME 1134 605
5 S 475 ASA 592 733
8 B 476 BAC^K 1132 413
17 S 477 AFGE 343 469
16 S 478 AXS 1750 565
17 B 479 AMPS 1512 594
11 C 341
2 C 259
11 B 482 AMPY 958 654
3 B 483 AORT 1332 378
28 C 375
15 B 485 BIP^A 1403 105
26 B 486 APH 1032 601
32 C 176
25 C 348
17 B 489 BARK 922 933
8 B 490 AC 438 784
37 C 289
7 S 492 ASGI 1211 98
19 C 382
8 C 167
2 S 495 AEVA 1166 71
23 C 243
3 S 497 AKR 1645 382
19 S 498 ARMK 1682 974
18 B 499 AXTA 534 631
7 C 170
30 C 270
8 B 502 ASPN 1994 617
32 C 187
16 C 327
33 S 505 BFS 1398 950
0 C 240
10 S 507 BBUC 201 393
34 C 421
7 B 509 AIG^A 1200 314
22 B 510 AHL^E 193 997
15 C 181
16 C 487
37 S 513 ALL 1626 434
22 B 514 APGB 1830 139
13 S 515 AVA 319 918
15 S 516 BMI 1329 738
17 S 517 BARK 752 581
5 B 518 AMC 618 970
25 S 519 AGR 1023 629
37 C 196
33 C 351
9 C 237
32 B 523 ALTG 253 675
23 S 524 AEE 184 758
17 B 525 AORT 1974 173
39 C 159
29 B 527 AKO/A 1574 532
17 S 528 AWP 422 466
10 S 529 APG 746 880
2 C 230
28 B 531 ANF 1881 162
6 B 532 ARCO 642 278
16 B 533 APCA 744 363
39 S 534 BFAC 507 357
2 C 447
13 S 536 BGX 1606 311
31 C 194
7 S 538 BGY 1283 598
3 S 539 BBAI 262 450
29 C 372
15 C 475
32 S 542 AUY 475 321
17 S 543 AZUL 1811 334
3 C 331
33 B 545 ASPN 940 730
29 S 546 BAH 365 163
17 B 547 BHR 332 259
17 C 440
10 S 549 AA 1424 689
31 S 550 AAIC^B 1748 338
2 S 551 ABG 488 933
5 C 109
15 B 553 ACA 1384 994
30 B 554 AC 453 676
21 S 555 BAC^L 344 143
34 S 556 BC^B 1379 50
15 C 253
9 B 558 AFG 653 664
2 S 559 AES 1691 773
18 S 560 ATH^A 670 432
19 S 561 ADC 1395 378
15 C 460
3 S 563 BME 832 989
24 S 564 AJXA 1720 521
12 C 111
