tests/complex_37.in
40
o
4 C 100
20 C 101
8 S 103 ARR^C 862 746
30 B 104 ARES 871 275
24 C 104
13 C 104
18 C 102
32 S 108 ASGI 1140 76
26 C 101
30 C 105
15 C 105
37 B 112 BMEZ 1703 509
37 S 113 ABEV 1386 590
23 C 112
38 S 115 BCAT 1526 699
13 C 115
33 C 116
39 B 118 BFS 627 656
5 C 102
39 C 110
15 C 114
12 C 121
21 S 123 ATH^E 204 263
32 C 110
32 S 125 BLD 636 358
28 B 126 AHL^D 840 88
8 C 119
37 S 128 ASH 220 256
32 S 129 BML^G 299 121
15 C 122
30 S 131 BEPC 861 438
28 C 109
38 C 114
17 S 134 ANET 690 244
24 S 135 BDJ 1144 232
33 C 125
30 B 137 BCSF 260 865
14 C 124
27 B 139 ASX 1738 218
24 C 128
33 B 141 APAM 1607 975
30 S 142 BBW 110 617
27 B 143 AVAL 505 248
27 C 105
7 B 145 BF/B 1534 948
35 S 146 BHK 1371 749
12 B 147 BBWI 1461 688
35 B 148 BEP^A 1284 664
29 B 149 AWP 1699 149
25 C 110
38 B 151 ATH^B 691 853
38 C 105
5 C 104
8 B 154 ALX 160 62
3 C 132
35 B 156 AMAM 1623 922
9 S 157 AHL^E 960 834
20 S 158 BAM 1064 421
7 B 159 ATH^C 476 208
7 B 160 BIP^B 1913 399
34 B 161 BMEZ 547 116
25 B 162 AGS 1219 878
4 B 163 ALCC 1202 768
0 S 164 BILL 1061 369
23 S 165 BMA 1246 889
29 B 166 AENZ 429 764
38 S 167 ALK 1419 758
0 C 159
22 S 169 BHG 724 81
35 C 141
10 C 161
22 S 172 ABR^F 877 243
25 C 130
17 B 174 ABB 255 149
15 C 168
1 B 176 AGCO 1821 656
22 B 177 AEFC 1991 796
33 S 178 AAT 1121 111
0 B 179 APCA 1218 616
27 C 134
0 B 181 ATTO 1834 246
35 B 182 ABR 277 171
25 B 183 ANVS 1669 885
18 B 184 AGR 1090 958
22 C 164
7 S 186 AVYA 430 241
36 S 187 BANC 821 983
21 C 166
20 C 163
23 B 190 BHVN 1956 354
6 B 191 ASIX 1664 735
26 B 192 ALEX 1887 859
7 S 193 AR 934 839
23 S 194 AOS 1653 516
29 S 195 AJX 1948 400
7 B 196 AP 761 331
5 S 197 BGR 1152 49
29 S 198 BDN 943 940
1 C 147
23 B 200 BKH 999 70
23 B 201 BGY 1044 569
25 C 154
10 B 203 AMP 205 616
18 S 204 AUB^A 1062 587
11 S 205 BHLB 1259 850
0 C 162
4 S 207 AER 1318 57
15 B 208 ACM 1642 938
3 B 209 AHT^F 370 869
16 B 210 AOS 1621 932
3 C 131
27 B 212 BEP 1673 464
38 S 213 AIRC 1317 238
1 C 179
5 B 215 ACCO 163 927
17 C 131
23 B 217 AP 551 800
24 B 218 ATCO^D 710 774
24 S 219 ARR^C 1075 368
4 S 220 BF/B 1849 562
3 S 221 BEPC 910 863
5 C 142
33 C 102
4 C 198
14 C 106
25 B 226 APAM 1364 862
17 S 227 AB 514 192
11 B 228 BBU 118 209
32 B 229 ARDC 576 324
10 S 230 ACM 1289 79
25 S 231 ATO 1649 899
17 C 172
32 C 160
0 B 234 BHE 225 606
25 C 222
18 B 236 AMWL 188 168
10 C 138
7 C 220
15 C 228
32 B 240 BME 1090 910
32 C 154
37 S 242 AEVA 1082 471
3 C 194
39 C 221
18 C 178
19 B 246 BAC^B 1255 530
9 S 247 ARLO 822 237
6 B 248 AMC 1207 761
1 C 164
21 B 250 AMWL 427 140
22 C 230
39 S 252 BBU 1833 511
34 S 253 AHT^G 525 301
26 B 254 AXR 285 180
0 C 235
21 S 256 ASGN 180 778
31 B 257 BKU 357 591
33 B 258 AUB^A 758 808
35 C 215
15 S 260 BLK 860 751
12 B 261 AXTA 238 549
31 B 262 AFGB 853 271
23 B 263 ARI 415 602
0 C 150
13 S 265 BGT 1767 514
32 S 266 AGM^C 1580 981
0 B 267 ALL^G 820 680
13 B 268 AWI 410 824
11 S 269 AMK 265 584
39 S 270 ARNC 874 387
26 B 271 AR 1267 388
26 S 272 AGR 1082 815
33 B 273 AVAL 495 80
30 S 274 ARES 1452 544
29 B 275 AA 1570 648
7 S 276 BGH 1772 102
35 B 277 ACR 1938 808
6 B 278 AAT 1855 587
31 C 122
37 S 280 AIN 1726 57
32 S 281 BHG 1616 601
12 B 282 BMEZ 1491 498
36 C 224
18 C 225
9 C 146
20 C 168
36 B 287 AVAL 1718 533
3 S 288 ACDI 1246 228
39 C 171
39 B 290 ANAC 1190 400
30 C 224
5 S 292 BAP 1108 984
2 S 293 AMP 816 792
12 S 294 AOD 894 586
16 B 295 AIF 198 61
27 S 296 AUD 659 871
11 S 297 ARGO 1077 132
27 B 298 AMRC 1034 879
13 C 179
31 C 292
34 B 301 AES 567 290
25 S 302 ABM 1815 499
4 C 136
32 C 264
20 B 305 BFAM 1390 741
24 B 306 AMH^G 1209 467
24 B 307 BIO 1744 21
21 S 308 BLX 709 222
34 S 309 ABR^F 356 250
12 B 310 ARES 130 456
39 S 311 AOS 1164 446
28 S 312 ACM 708 771
13 B 313 ARLO 522 923
6 C 261
23 B 315 ACP 1934 244
35 C 269
3 B 317 AHL^C 807 233
16 S 318 ADM 989 608
30 C 274
21 C 113
22 C 298
23 B 322 BKKT 1441 310
16 S 323 AZRE 1716 438
12 B 324 BHR 388 256
28 S 325 ARW 1554 266
39 C 282
13 S 327 ATCO^H 969 199
10 C 123
25 S 329 AQNA 1195 682
37 B 330 ATCO^H 1661 339
18 B 331 AJRD 297 933
6 S 332 AMAM 798 301
16 C 153
29 B 334 AEFC 1388 154
27 S 335 BAC^P 1461 749
27 C 227
34 C 250
14 C 268
1 C 284
25 C 142
37 S 341 AMOV 1709 729
14 S 342 BGT 431 111
7 S 343 AON 606 382
25 B 344 ACRE 1817 59
19 C 160
7 B 346 ASA 1704 241
1 S 347 ABC 257 987
18 C 102
38 C 237
4 S 350 BCC 326 930
2 C 305
10 B 352 AIZ 1909 308
7 B 353 AEG 1489 609
25 B 354 ATCO 1917 729
1 B 355 BLW 871 623
14 C 120
15 S 357 BE 588 240
32 B 358 AYI 1289 694
24 B 359 BAX 1691 63
30 B 360 AGS 1191 278
5 C 246
28 S 362 ARCH 482 338
14 S 363 APE 1989 174
27 C 189
12 C 311
19 B 366 ALL^I 502 663
36 C 269
15 S 368 ATH^C 714 624
26 S 369 AKR 816 639
28 B 370 ATKR 883 33
22 C 328
35 C 114
28 B 373 BANC 1362 681
7 S 374 BHR 1036 159
23 S 375 ASG 1431 347
1 S 376 ACP^A 1576 309
27 C 253
27 C 318
26 B 379 BJ 1346 381
11 B 380 AGR 931 615
15 B 381 AZZ 183 933
13 S 382 ATO 690 100
10 B 383 ATO 307 224
28 C 206
16 B 385 BLUA 1696 960
5 C 200
34 B 387 BFLY 1223 623
6 C 206
12 B 389 AQUA 1995 408
22 C 321
35 B 391 AMH^H 1832 336
39 B 392 ASB^E 175 840
26 S 393 AFL 1300 779
3 B 394 BHG 1588 937
19 S 395 BLD 705 905
2 S 396 ATCO^H 397 414
27 S 397 BAC^S 640 301
7 C 158
20 C 229
31 S 400 AVTR 536 571
3 C 211
0 B 402 BBDO 1553 574
4 B 403 AQNA 915 599
14 B 404 BBW 1830 393
3 S 405 BHIL 791 164
22 C 174
21 C 406
5 S 408 BEKE 190 964
13 S 409 BFH 895 297
37 S 410 BANC 1885 478
9 B 411 BMAC 1419 931
34 B 412 BHR 640 526
18 B 413 BBVA 953 246
28 B 414 BBLN 1272 320
30 C 258
35 B 416 AYX 388 736
32 B 417 AQN 1395 359
13 B 418 AUD 1160 163
33 S 419 AHH 498 948
20 C 195
6 B 421 BBLN 102 351
31 C 124
8 C 231
24 S 424 APTV^A 881 396
30 C 370
25 B 426 ARGD 128 461
35 S 427 ANAC 1151 171
6 C 198
0 B 429 BC^C 1288 982
5 C 275
28 C 138
21 C 325
17 C 128
13 S 434 ASH 1028 336
19 C 400
16 S 436 AORT 1301 634
22 B 437 APAM 924 162
10 C 163
35 S 439 APRN 1318 26
28 B 440 AMPX 1556 209
1 S 441 ADM 621 409
39 S 442 ARR^C 1780 939
28 B 443 AON 553 46
10 C 277
2 C 287
33 S 446 BACA 413 374
28 S 447 AEVA 491 599
38 C 134
2 B 449 AMK 1759 363
1 S 450 ARR 1615 913
34 S 451 AMTD 1923 371
26 S 452 BFAM 1380 159
34 S 453 ASH 1579 655
31 S 454 AVYA 931 239
24 C 261
13 B 456 BBWI 1522 462
5 S 457 ARR^C 1780 251
13 B 458 AEM 1604 384
29 S 459 BCH 421 644
15 S 460 AHT 1315 205
15 S 461 BBAR 302 273
28 B 462 BGH 942 616
24 B 463 ALEX 622 143
39 S 464 AGM^F 738 547
7 B 465 ALLG 126 864
27 S 466 AMP 806 239
26 S 467 BMI 892 320
35 B 468 BEPC 683 429
20 S 469 BIP 625 434
32 C 372
38 S 471 BBVA 1001 811
32 C 213
25 S 473 AIF 548 598
13 B 474 ABM 1234 344
32 B 475 AAC 572 268
35 B 476 BLDR 1922 974
14 B 477 BFH 1752 427
31 B 478 AI 804 319
23 B 479 BAC^L 1531 318
28 B 480 BC^C 1220 844
12 B 481 ALLE 988 689
31 S 482 AHH^A 1853 974
0 C 424
5 B 484 BGB 445 602
9 S 485 BG 971 446
5 C 228
7 C 216
35 B 488 ABG 1031 356
31 C 282
4 S 490 BIPH 858 212
11 B 491 ACP 187 450
27 C 325
26 S 493 ALTG 451 201
33 C 355
6 B 495 BACA 1947 161
39 C 159
25 S 497 ATCO^I 1697 407
33 B 498 BIGZ 286 190
9 B 499 AES 239 728
3 C 261
8 S 501 AU 598 957
34 B 502 AEVA 876 715
7 C 202
27 B 504 BIGZ 1465 643
32 S 505 ACR 421 875
21 C 259
23 C 315
21 B 508 AAN 296 31
28 C 488
28 C 494
27 S 511 ALL 1674 621
37 C 466
31 S 513 AIF 612 669
1 S 514 BFK 392 903
7 S 515 AC 970 812
34 S 516 ABR^E 1641 678
9 C 443
17 S 518 BGB 1353 791
27 B 519 AMPS 354 667
16 B 520 BKSY 637 240
9 S 521 ACRE 235 847
8 S 522 AAC 765 904
1 B 523 AEL 302 940
11 C 345
4 C 518
19 C 226
34 B 527 AMBP 1570 331
14 C 318
39 C 465
37 B 530 AIT 1413 119
10 B 531 BML^J 346 924
23 B 532 ACR^D 765 919
12 C 162
21 C 269
37 B 535 AEVA 1138 79
3 B 536 AXL 1088 56
16 C 504
27 S 538 ABR^F 1763 634
11 B 539 BBN 647 272
34 C 144
20 C 517
26 B 542 APH 1813 621
5 B 543 AIF 1291 74
33 C 446
7 B 545 AMC 360 88
27 C 411
4 B 547 BCX 138 369
34 S 548 BB 1387 135
32 S 549 AAN 200 864
17 B 550 BBDC 1863 45
30 B 551 AMH 603 745
2 S 552 BHP 1969 446
38 B 553 APGB 1048 495
6 S 554 AQNB 1397 105
39 C 245
18 S 556 BLD 1651 120
3 B 557 AAIC^C 1031 723
27 B 558 BC^C 629 865
22 B 559 BDXB 1103 891
